Workbook

Sheet Dashboard
B2: NIKE, Inc. - financial performance FY2020 to FY2026
B3: USD millions unless stated. Source: NIKE 10-K filings via the SEC XBRL API. Financial year ends 31 May.
B5: FY2026 revenue | D5: FY2026 operating income | F5: FY2026 net income
B6: ='Income statement'!H5 -> 0 | D6: ='Income statement'!H11 -> 0 | F6: ='Income statement'!H16 -> 0
B8: FY2026 gross margin | D8: FY2026 operating margin | F8: FY2026 diluted EPS
B9: =Ratios!H5 -> 0 | D9: =Ratios!H6 -> 0 | F9: ='Income statement'!H17 -> 0
B63: Operating income is gross profit less SG&A - NIKE does not report an operating income line. See the Read me tab.

Sheet Income statement
A1: NIKE, Inc. - income statement as reported
A2: USD millions, except per-share amounts. Financial year ends 31 May. Source: NIKE 10-K filings via the SEC XBRL company facts API. Only the reported lines are typed in; operating income, pre-tax income, net income, the common-size block and the growth block are formulas.
A4: USD millions | B4: FY2020 | C4: FY2021 | D4: FY2022 | E4: FY2023 | F4: FY2024 | G4: FY2025 | H4: FY2026
A5: Revenue | B5: 37403 | C5: 44538 | D5: 46710 | E5: 51217 | F5: 51362 | G5: 46309 | H5: 46398
A6: Cost of sales | B6: 21162 | C6: 24576 | D6: 25231 | E6: 28925 | F6: 28475 | G6: 26519 | H6: 26487
A7: Gross profit | B7: 16241 | C7: 19962 | D7: 21479 | E7: 22292 | F7: 22887 | G7: 19790 | H7: 19911
A8: Demand creation expense | B8: 3592 | C8: 3114 | D8: 3850 | E8: 4060 | F8: 4285 | G8: 4689 | H8: 4754
A9: Operating overhead expense | B9: 9534 | C9: 9911 | D9: 10954 | E9: 12317 | F9: 12291 | G9: 11399 | H9: 11360
A10: Total selling and administrative expense | B10: 13126 | C10: 13025 | D10: 14804 | E10: 16377 | F10: 16576 | G10: 16088 | H10: 16114
A11: Operating income (gross profit less SG&A) | B11: =B7-B10 -> 0 | C11: =C7-C10 -> 0 | D11: =D7-D10 -> 0 | E11: =E7-E10 -> 0 | F11: =F7-F10 -> 0 | G11: =G7-G10 -> 0 | H11: =H7-H10 -> 0
A12: Interest income (expense), net | B12: -89 | C12: -262 | D12: -205 | E12: 6 | F12: 161 | G12: 107 | H12: 50
A13: Other income (expense), net | B13: -139 | C13: -14 | D13: 181 | E13: 280 | F13: 228 | G13: 76 | H13: 53
A14: Income before income taxes | B14: =B11+B12+B13 -> 0 | C14: =C11+C12+C13 -> 0 | D14: =D11+D12+D13 -> 0 | E14: =E11+E12+E13 -> 0 | F14: =F11+F12+F13 -> 0 | G14: =G11+G12+G13 -> 0 | H14: =H11+H12+H13 -> 0
A15: Income tax expense | B15: 348 | C15: 934 | D15: 605 | E15: 1131 | F15: 1000 | G15: 666 | H15: 792
A16: Net income | B16: =B14-B15 -> 0 | C16: =C14-C15 -> 0 | D16: =D14-D15 -> 0 | E16: =E14-E15 -> 0 | F16: =F14-F15 -> 0 | G16: =G14-G15 -> 0 | H16: =H14-H15 -> 0
A17: Diluted earnings per share | B17: 1.6 | C17: 3.6 | D17: 3.8 | E17: 3.2 | F17: 3.7 | G17: 2.2 | H17: 2.1
A18: Diluted shares (millions) | B18: 1591.6 | C18: 1609.4 | D18: 1610.8 | E18: 1569.8 | F18: 1529.7 | G18: 1487.6 | H18: 1481
A20: As a percentage of revenue | B20: FY2020 | C20: FY2021 | D20: FY2022 | E20: FY2023 | F20: FY2024 | G20: FY2025 | H20: FY2026
A21: Gross margin | B21: =B7/B$5 -> 0 | C21: =C7/C$5 -> 0 | D21: =D7/D$5 -> 0 | E21: =E7/E$5 -> 0 | F21: =F7/F$5 -> 0 | G21: =G7/G$5 -> 0 | H21: =H7/H$5 -> 0
A22: Demand creation expense | B22: =B8/B$5 -> 0 | C22: =C8/C$5 -> 0 | D22: =D8/D$5 -> 0 | E22: =E8/E$5 -> 0 | F22: =F8/F$5 -> 0 | G22: =G8/G$5 -> 0 | H22: =H8/H$5 -> 0
A23: Operating overhead expense | B23: =B9/B$5 -> 0 | C23: =C9/C$5 -> 0 | D23: =D9/D$5 -> 0 | E23: =E9/E$5 -> 0 | F23: =F9/F$5 -> 0 | G23: =G9/G$5 -> 0 | H23: =H9/H$5 -> 0
A24: Total SG&A | B24: =B10/B$5 -> 0 | C24: =C10/C$5 -> 0 | D24: =D10/D$5 -> 0 | E24: =E10/E$5 -> 0 | F24: =F10/F$5 -> 0 | G24: =G10/G$5 -> 0 | H24: =H10/H$5 -> 0
A25: Operating margin | B25: =B11/B$5 -> 0 | C25: =C11/C$5 -> 0 | D25: =D11/D$5 -> 0 | E25: =E11/E$5 -> 0 | F25: =F11/F$5 -> 0 | G25: =G11/G$5 -> 0 | H25: =H11/H$5 -> 0
A26: Net margin | B26: =B16/B$5 -> 0 | C26: =C16/C$5 -> 0 | D26: =D16/D$5 -> 0 | E26: =E16/E$5 -> 0 | F26: =F16/F$5 -> 0 | G26: =G16/G$5 -> 0 | H26: =H16/H$5 -> 0
A29: Year-on-year growth | B29: FY2020 | C29: FY2021 | D29: FY2022 | E29: FY2023 | F29: FY2024 | G29: FY2025 | H29: FY2026
A30: Revenue | B30: n/a | C30: =C5/B5-1 -> 0 | D30: =D5/C5-1 -> 0 | E30: =E5/D5-1 -> 0 | F30: =F5/E5-1 -> 0 | G30: =G5/F5-1 -> 0 | H30: =H5/G5-1 -> 0
A31: Gross profit | B31: n/a | C31: =C7/B7-1 -> 0 | D31: =D7/C7-1 -> 0 | E31: =E7/D7-1 -> 0 | F31: =F7/E7-1 -> 0 | G31: =G7/F7-1 -> 0 | H31: =H7/G7-1 -> 0
A32: Total SG&A | B32: n/a | C32: =C10/B10-1 -> 0 | D32: =D10/C10-1 -> 0 | E32: =E10/D10-1 -> 0 | F32: =F10/E10-1 -> 0 | G32: =G10/F10-1 -> 0 | H32: =H10/G10-1 -> 0
A33: Operating income | B33: n/a | C33: =C11/B11-1 -> 0 | D33: =D11/C11-1 -> 0 | E33: =E11/D11-1 -> 0 | F33: =F11/E11-1 -> 0 | G33: =G11/F11-1 -> 0 | H33: =H11/G11-1 -> 0
A34: Net income | B34: n/a | C34: =C16/B16-1 -> 0 | D34: =D16/C16-1 -> 0 | E34: =E16/D16-1 -> 0 | F34: =F16/E16-1 -> 0 | G34: =G16/F16-1 -> 0 | H34: =H16/G16-1 -> 0
A37: NIKE does not report an operating income line. Its income statement goes straight from gross profit to SG&A to pre-tax income, so operating income here is gross profit less SG&A - what is usually called EBIT for this company. The formula is visible in row 11.

Sheet Balance sheet
A1: NIKE, Inc. - balance sheet and cash flow items
A2: USD millions at 31 May of each year. Free cash flow and total cash returned to shareholders are formulas.
A4: USD millions | B4: FY2020 | C4: FY2021 | D4: FY2022 | E4: FY2023 | F4: FY2024 | G4: FY2025 | H4: FY2026
A5: Cash and cash equivalents | B5: 8348 | C5: 9889 | D5: 8574 | E5: 7441 | F5: 9860 | G5: 7464 | H5: 7563
A6: Accounts receivable, net | B6: 2749 | C6: 4463 | D6: 4667 | E6: 4131 | F6: 4427 | G6: 4717 | H6: 5931
A7: Inventories | B7: 7367 | C7: 6854 | D7: 8420 | E7: 8454 | F7: 7519 | G7: 7489 | H7: 7501
A8: Total current assets | B8: 20556 | C8: 26291 | D8: 28213 | E8: 25202 | F8: 25382 | G8: 23362 | H8: 24603
A9: Total assets | B9: 31342 | C9: 37740 | D9: 40321 | E9: 37531 | F9: 38110 | G9: 36579 | H9: 38410
A10: Total current liabilities | B10: 8284 | C10: 9674 | D10: 10730 | E10: 9256 | F10: 10593 | G10: 10566 | H10: 12547
A11: Long-term debt | B11: 9406 | C11: 9413 | D11: 8920 | E11: 8927 | F11: 7903 | G11: 7961 | H11: 5942
A12: Shareholders' equity | B12: 8055 | C12: 12767 | D12: 15281 | E12: 14004 | F12: 14430 | G12: 13213 | H12: 14865
A14: Cash from operating activities | B14: 2485 | C14: 6657 | D14: 5188 | E14: 5841 | F14: 7429 | G14: 3698 | H14: 2868
A15: Capital expenditure | B15: 1086 | C15: 695 | D15: 758 | E15: 969 | F15: 812 | G15: 430 | H15: 684
A16: Free cash flow | B16: =B14-B15 -> 0 | C16: =C14-C15 -> 0 | D16: =D14-D15 -> 0 | E16: =E14-E15 -> 0 | F16: =F14-F15 -> 0 | G16: =G14-G15 -> 0 | H16: =H14-H15 -> 0
A17: Dividends paid | B17: 1452 | C17: 1638 | D17: 1837 | E17: 2012 | F17: 2169 | G17: 2300 | H17: 2407
A18: Share buybacks | B18: 3067 | C18: 608 | D18: 4014 | E18: 5480 | F18: 4250 | G18: 2985 | H18: 146
A19: Total returned to shareholders | B19: =B17+B18 -> 0 | C19: =C17+C18 -> 0 | D19: =D17+D18 -> 0 | E19: =E17+E18 -> 0 | F19: =F17+F18 -> 0 | G19: =G17+G18 -> 0 | H19: =H17+H18 -> 0
A22: Capital expenditure and the shareholder return lines are reported as cash outflows but tagged as positive amounts, so free cash flow is operating cash flow minus capital expenditure.

Sheet Ratios
A1: NIKE, Inc. - ratio analysis
A2: Every cell on this sheet is a formula pointing at the Income statement or Balance sheet tab. Nothing is typed in.
A4: Profitability | B4: FY2020 | C4: FY2021 | D4: FY2022 | E4: FY2023 | F4: FY2024 | G4: FY2025 | H4: FY2026
A5: Gross margin | B5: ='Income statement'!B7/'Income statement'!B5 -> 0 | C5: ='Income statement'!C7/'Income statement'!C5 -> 0 | D5: ='Income statement'!D7/'Income statement'!D5 -> 0 | E5: ='Income statement'!E7/'Income statement'!E5 -> 0 | F5: ='Income statement'!F7/'Income statement'!F5 -> 0 | G5: ='Income statement'!G7/'Income statement'!G5 -> 0 | H5: ='Income statement'!H7/'Income statement'!H5 -> 0
A6: Operating margin | B6: ='Income statement'!B11/'Income statement'!B5 -> 0 | C6: ='Income statement'!C11/'Income statement'!C5 -> 0 | D6: ='Income statement'!D11/'Income statement'!D5 -> 0 | E6: ='Income statement'!E11/'Income statement'!E5 -> 0 | F6: ='Income statement'!F11/'Income statement'!F5 -> 0 | G6: ='Income statement'!G11/'Income statement'!G5 -> 0 | H6: ='Income statement'!H11/'Income statement'!H5 -> 0
A7: Net margin | B7: ='Income statement'!B16/'Income statement'!B5 -> 0 | C7: ='Income statement'!C16/'Income statement'!C5 -> 0 | D7: ='Income statement'!D16/'Income statement'!D5 -> 0 | E7: ='Income statement'!E16/'Income statement'!E5 -> 0 | F7: ='Income statement'!F16/'Income statement'!F5 -> 0 | G7: ='Income statement'!G16/'Income statement'!G5 -> 0 | H7: ='Income statement'!H16/'Income statement'!H5 -> 0
A8: SG&A as % of revenue | B8: ='Income statement'!B10/'Income statement'!B5 -> 0 | C8: ='Income statement'!C10/'Income statement'!C5 -> 0 | D8: ='Income statement'!D10/'Income statement'!D5 -> 0 | E8: ='Income statement'!E10/'Income statement'!E5 -> 0 | F8: ='Income statement'!F10/'Income statement'!F5 -> 0 | G8: ='Income statement'!G10/'Income statement'!G5 -> 0 | H8: ='Income statement'!H10/'Income statement'!H5 -> 0
A9: Effective tax rate | B9: ='Income statement'!B15/'Income statement'!B14 -> 0 | C9: ='Income statement'!C15/'Income statement'!C14 -> 0 | D9: ='Income statement'!D15/'Income statement'!D14 -> 0 | E9: ='Income statement'!E15/'Income statement'!E14 -> 0 | F9: ='Income statement'!F15/'Income statement'!F14 -> 0 | G9: ='Income statement'!G15/'Income statement'!G14 -> 0 | H9: ='Income statement'!H15/'Income statement'!H14 -> 0
A12: Liquidity and working capital | B12: FY2020 | C12: FY2021 | D12: FY2022 | E12: FY2023 | F12: FY2024 | G12: FY2025 | H12: FY2026
A13: Current ratio | B13: ='Balance sheet'!B8/'Balance sheet'!B10 -> 0 | C13: ='Balance sheet'!C8/'Balance sheet'!C10 -> 0 | D13: ='Balance sheet'!D8/'Balance sheet'!D10 -> 0 | E13: ='Balance sheet'!E8/'Balance sheet'!E10 -> 0 | F13: ='Balance sheet'!F8/'Balance sheet'!F10 -> 0 | G13: ='Balance sheet'!G8/'Balance sheet'!G10 -> 0 | H13: ='Balance sheet'!H8/'Balance sheet'!H10 -> 0
A14: Inventory days | B14: ='Balance sheet'!B7/'Income statement'!B6*365 -> 0 | C14: ='Balance sheet'!C7/'Income statement'!C6*365 -> 0 | D14: ='Balance sheet'!D7/'Income statement'!D6*365 -> 0 | E14: ='Balance sheet'!E7/'Income statement'!E6*365 -> 0 | F14: ='Balance sheet'!F7/'Income statement'!F6*365 -> 0 | G14: ='Balance sheet'!G7/'Income statement'!G6*365 -> 0 | H14: ='Balance sheet'!H7/'Income statement'!H6*365 -> 0
A15: Receivable days | B15: ='Balance sheet'!B6/'Income statement'!B5*365 -> 0 | C15: ='Balance sheet'!C6/'Income statement'!C5*365 -> 0 | D15: ='Balance sheet'!D6/'Income statement'!D5*365 -> 0 | E15: ='Balance sheet'!E6/'Income statement'!E5*365 -> 0 | F15: ='Balance sheet'!F6/'Income statement'!F5*365 -> 0 | G15: ='Balance sheet'!G6/'Income statement'!G5*365 -> 0 | H15: ='Balance sheet'!H6/'Income statement'!H5*365 -> 0
A16: Long-term debt to equity | B16: ='Balance sheet'!B11/'Balance sheet'!B12 -> 0 | C16: ='Balance sheet'!C11/'Balance sheet'!C12 -> 0 | D16: ='Balance sheet'!D11/'Balance sheet'!D12 -> 0 | E16: ='Balance sheet'!E11/'Balance sheet'!E12 -> 0 | F16: ='Balance sheet'!F11/'Balance sheet'!F12 -> 0 | G16: ='Balance sheet'!G11/'Balance sheet'!G12 -> 0 | H16: ='Balance sheet'!H11/'Balance sheet'!H12 -> 0
A19: Returns and cash | B19: FY2020 | C19: FY2021 | D19: FY2022 | E19: FY2023 | F19: FY2024 | G19: FY2025 | H19: FY2026
A20: Return on equity (average equity) | B20: n/a | C20: ='Income statement'!C16/AVERAGE('Balance sheet'!B12,'Balance sheet'!C12) -> 0 | D20: ='Income statement'!D16/AVERAGE('Balance sheet'!C12,'Balance sheet'!D12) -> 0 | E20: ='Income statement'!E16/AVERAGE('Balance sheet'!D12,'Balance sheet'!E12) -> 0 | F20: ='Income statement'!F16/AVERAGE('Balance sheet'!E12,'Balance sheet'!F12) -> 0 | G20: ='Income statement'!G16/AVERAGE('Balance sheet'!F12,'Balance sheet'!G12) -> 0 | H20: ='Income statement'!H16/AVERAGE('Balance sheet'!G12,'Balance sheet'!H12) -> 0
A21: Return on assets (average assets) | B21: n/a | C21: ='Income statement'!C16/AVERAGE('Balance sheet'!B9,'Balance sheet'!C9) -> 0 | D21: ='Income statement'!D16/AVERAGE('Balance sheet'!C9,'Balance sheet'!D9) -> 0 | E21: ='Income statement'!E16/AVERAGE('Balance sheet'!D9,'Balance sheet'!E9) -> 0 | F21: ='Income statement'!F16/AVERAGE('Balance sheet'!E9,'Balance sheet'!F9) -> 0 | G21: ='Income statement'!G16/AVERAGE('Balance sheet'!F9,'Balance sheet'!G9) -> 0 | H21: ='Income statement'!H16/AVERAGE('Balance sheet'!G9,'Balance sheet'!H9) -> 0
A22: Free cash flow as % of revenue | B22: ='Balance sheet'!B16/'Income statement'!B5 -> 0 | C22: ='Balance sheet'!C16/'Income statement'!C5 -> 0 | D22: ='Balance sheet'!D16/'Income statement'!D5 -> 0 | E22: ='Balance sheet'!E16/'Income statement'!E5 -> 0 | F22: ='Balance sheet'!F16/'Income statement'!F5 -> 0 | G22: ='Balance sheet'!G16/'Income statement'!G5 -> 0 | H22: ='Balance sheet'!H16/'Income statement'!H5 -> 0
A23: Cash returned as % of free cash flow | B23: ='Balance sheet'!B19/'Balance sheet'!B16 -> 0 | C23: ='Balance sheet'!C19/'Balance sheet'!C16 -> 0 | D23: ='Balance sheet'!D19/'Balance sheet'!D16 -> 0 | E23: ='Balance sheet'!E19/'Balance sheet'!E16 -> 0 | F23: ='Balance sheet'!F19/'Balance sheet'!F16 -> 0 | G23: ='Balance sheet'!G19/'Balance sheet'!G16 -> 0 | H23: ='Balance sheet'!H19/'Balance sheet'!H16 -> 0
A26: Return on equity and return on assets use the average of the opening and closing balance, because profit is earned across the year while the balance sheet is a single-day snapshot. FY2020 has no opening balance in this dataset, so it shows n/a.

Sheet Margin bridge
A1: Why operating income fell $2,514m between FY2024 and FY2026
A2: The three effects are formulas pointing at the Income statement tab, so they stay correct if the figures change. They add back to the actual change, which row 12 checks.
A4: Item | B4: USD m | C4: How it is calculated
A5: FY2024 operating income | B5: ='Income statement'!F11 -> 0 | C5: as reported
A6: Effect of lower revenue | B6: =('Income statement'!H5-'Income statement'!F5)*('Income statement'!F7/'Income statement'!F5) -> 0 | C6: change in revenue x the FY2024 gross margin
A7: Effect of lower gross margin | B7: ='Income statement'!H5*('Income statement'!H7/'Income statement'!H5-'Income statement'!F7/'Income statement'!F5) -> 0 | C7: FY2026 revenue x the change in gross margin
A8: Effect of change in SG&A | B8: =-('Income statement'!H10-'Income statement'!F10) -> 0 | C8: minus the change in SG&A (a fall in SG&A helps profit)
A9: FY2026 operating income | B9: ='Income statement'!H11 -> 0 | C9: as reported
A11: Check: FY2024 + the three effects | B11: =B5+B6+B7+B8 -> 0
A12: Difference from reported FY2026 | B12: =B11-B9 -> 0 | C12: should be zero

Sheet Forecast
A1: Simple three-scenario forecast, FY2027 and FY2028
A2: This is not a valuation. It answers one question: if revenue and margins behave in a stated way, what happens to profit? Every shaded cell is an assumption you can change - the three scenario blocks below recalculate automatically. The last column of the 'What the last seven years did' table is there so each assumption can be compared with history.
A4: Assumptions (change the shaded cells)
B5: Low | C5: Base | D5: High
A6: Revenue growth per year | B6: -0.02 | C6: 0.02 | D6: 0.05
A7: Gross margin | B7: 0.42 | C7: 0.435 | D7: 0.445
A8: SG&A growth per year | B8: 0.01 | C8: 0.02 | D8: 0.02
A9: Effective tax rate | B9: 0.2 | C9: 0.2 | D9: 0.2
A10: Diluted share count change per year | B10: -0.01 | C10: -0.015 | D10: -0.015
A12: Non-operating income, held flat ($m) | B12: ='Income statement'!H12+'Income statement'!H13 -> 0 | C12: interest plus other income as reported in FY2026
A14: What the last seven years did (FY2020-FY2026) | B14: Average | C14: Lowest | D14: Highest | E14: FY2026
A15: Revenue growth % | B15: 0.0404 | C15: -0.0984 | D15: 0.1908 | E15: 0.0019
A16: Gross margin % | B16: 0.4399 | C16: 0.4273 | D16: 0.4598 | E16: 0.4291
A17: SG&A growth % | B17: 0.0366 | C17: -0.0294 | D17: 0.1366 | E17: 0.0016
A18: Effective tax rate % | B18: 0.1511 | C18: 0.091 | D18: 0.2031 | E18: 0.2031
A19: Diluted share count change % | B19: -0.0118 | C19: -0.0275 | D19: 0.0112 | E19: -0.0044
A22: Low case - revenue falls 2% a year, gross margin 42.0%, SG&A trimmed 1% a year
A23: Revenue | B23: ='Income statement'!H5 -> 0 | C23: =B23*(1+$B$6) -> 0 | D23: =C23*(1+$B$6) -> 0
A24: Gross profit | B24: ='Income statement'!H7 -> 0 | C24: =C23*$B$7 -> 0 | D24: =D23*$B$7 -> 0
A25: Gross margin | B25: =B24/B23 -> 0 | C25: =C24/C23 -> 0 | D25: =D24/D23 -> 0
A26: SG&A | B26: ='Income statement'!H10 -> 0 | C26: =B26*(1+$B$8) -> 0 | D26: =C26*(1+$B$8) -> 0
A27: SG&A as % of revenue | B27: =B26/B23 -> 0 | C27: =C26/C23 -> 0 | D27: =D26/D23 -> 0
A28: Operating income | B28: =B24-B26 -> 0 | C28: =C24-C26 -> 0 | D28: =D24-D26 -> 0
A29: Operating margin | B29: =B28/B23 -> 0 | C29: =C28/C23 -> 0 | D29: =D28/D23 -> 0
A30: Non-operating income | B30: =$B$12 -> 0 | C30: =$B$12 -> 0 | D30: =$B$12 -> 0
A31: Income before income taxes | B31: =B28+B30 -> 0 | C31: =C28+C30 -> 0 | D31: =D28+D30 -> 0
A32: Income tax expense | B32: ='Income statement'!H15 -> 0 | C32: =C31*$B$9 -> 0 | D32: =D31*$B$9 -> 0
A33: Net income | B33: =B31-B32 -> 0 | C33: =C31-C32 -> 0 | D33: =D31-D32 -> 0
A34: Net margin | B34: =B33/B23 -> 0 | C34: =C33/C23 -> 0 | D34: =D33/D23 -> 0
A35: Diluted shares (millions) | B35: ='Income statement'!H18 -> 0 | C35: =B35*(1+$B$10) -> 0 | D35: =C35*(1+$B$10) -> 0
A36: Diluted EPS | B36: =B33/B35 -> 0 | C36: =C33/C35 -> 0 | D36: =D33/D35 -> 0
A40: Base case - revenue grows 2% a year, gross margin recovers to 43.5%, SG&A grows 2%
A41: Revenue | B41: ='Income statement'!H5 -> 0 | C41: =B41*(1+$C$6) -> 0 | D41: =C41*(1+$C$6) -> 0
A42: Gross profit | B42: ='Income statement'!H7 -> 0 | C42: =C41*$C$7 -> 0 | D42: =D41*$C$7 -> 0
A43: Gross margin | B43: =B42/B41 -> 0 | C43: =C42/C41 -> 0 | D43: =D42/D41 -> 0
A44: SG&A | B44: ='Income statement'!H10 -> 0 | C44: =B44*(1+$C$8) -> 0 | D44: =C44*(1+$C$8) -> 0
A45: SG&A as % of revenue | B45: =B44/B41 -> 0 | C45: =C44/C41 -> 0 | D45: =D44/D41 -> 0
A46: Operating income | B46: =B42-B44 -> 0 | C46: =C42-C44 -> 0 | D46: =D42-D44 -> 0
A47: Operating margin | B47: =B46/B41 -> 0 | C47: =C46/C41 -> 0 | D47: =D46/D41 -> 0
A48: Non-operating income | B48: =$B$12 -> 0 | C48: =$B$12 -> 0 | D48: =$B$12 -> 0
...

Sheet Read me
B2: NIKE, Inc. financial performance analysis
B4: What this workbook is
B5: Seven financial years of NIKE's reported results (FY2020 to FY2026), the margins and ratios derived from them, an explanation of why operating income fell between FY2024 and FY2026, and a simple three-scenario forecast of FY2027 and FY2028.
B7: Where the figures come from
B8: NIKE's own 10-K filings, read through the SEC's XBRL company facts API (data.sec.gov). The API is free and needs no key. A Python script downloads the file and writes out the line items; nothing in this workbook is typed in by hand except the forecast assumptions.
B10: NIKE's financial year ends on 31 May, so FY2026 covers June 2025 to May 2026.
B12: Checks that were run on the extracted data
B13: Four reconciliations, all of which come to zero: revenue less cost of sales equals reported gross profit; demand creation plus operating overhead equals reported SG&A; operating income plus interest plus other income equals reported pre-tax income; and pre-tax income less tax equals reported net income.
B15: One thing to know about operating income
B16: NIKE does not report an operating income line. Its income statement goes from gross profit straight to SG&A and then to pre-tax income. Operating income here is gross profit less SG&A, which is what is normally called EBIT for this company. The formula is visible in the Income statement tab.
B18: What this workbook is not
B19: It is not a valuation, a DCF or an investment recommendation. The forecast is a sensitivity exercise: it shows what happens to profit under stated assumptions about revenue growth and margins. The assumptions are mine and they are all visible in shaded cells on the Forecast tab, next to what the last seven years actually did.
... B22: Dashboard - headline figures and charts Income statement - as reported, plus common-size and growth blocks Balance sheet - balance sheet and cash flow items Ratios - profitability, liquidity, working capital and returns Margin bridge - the three causes of the fall in operating income Forecast - three scenarios driven by the assumptions block
